#VRML_SIM R2023b utf8

EXTERNPROTO "https://raw.githubusercontent.com/cyberbotics/webots/R2023b/projects/objects/backgrounds/protos/TexturedBackground.proto"
EXTERNPROTO "https://raw.githubusercontent.com/cyberbotics/webots/R2023b/projects/objects/backgrounds/protos/TexturedBackgroundLight.proto"
EXTERNPROTO "https://raw.githubusercontent.com/cyberbotics/webots/R2023b/projects/objects/floors/protos/RectangleArena.proto"
EXTERNPROTO "https://raw.githubusercontent.com/cyberbotics/webots/R2023b/projects/appearances/protos/DamascusSteel.proto"
EXTERNPROTO "https://raw.githubusercontent.com/cyberbotics/webots/R2023b/projects/appearances/protos/RustyMetal.proto"
EXTERNPROTO "https://raw.githubusercontent.com/cyberbotics/webots/R2023b/projects/appearances/protos/VarnishedPine.proto"
EXTERNPROTO "https://raw.githubusercontent.com/cyberbotics/webots/R2023b/projects/appearances/protos/Pcb.proto"
EXTERNPROTO "https://raw.githubusercontent.com/cyberbotics/webots/R2023b/projects/appearances/protos/BlanketFabric.proto"
EXTERNPROTO "https://raw.githubusercontent.com/cyberbotics/webots/R2023b/projects/appearances/protos/Grass.proto"

WorldInfo {
}
Viewpoint {
  orientation 0.05461094859471456 0.07097656710147297 -0.9959819130968571 1.3154737462365822
  position -0.6914942277792422 1.2993756918754666 0.5038213524508764
}
TexturedBackground {
}
TexturedBackgroundLight {
}
RectangleArena {
  floorSize 5 5
}
Robot {
  translation 0 0 0.3
  children [
    DEF solid_body Solid {
      children [
        DEF body Shape {
          appearance DamascusSteel {
          }
          geometry Box {
            size 0.5 0.8 0.1
          }
        }
      ]
      name "solid(1)"
      boundingObject Box {
        size 0.04 0.05 0.01
      }
      physics Physics {
      }
    }
    DEF FR HingeJoint {
      jointParameters HingeJointParameters {
        anchor 0.25 0.3 0
      }
      device [
        RotationalMotor {
        }
      ]
      endPoint Solid {
        translation 0.25 0.3 -0.1
        rotation 1 0 0 0
        children [
          HingeJoint {
            jointParameters HingeJointParameters {
              anchor 0 0 -0.1
            }
            device [
              RotationalMotor {
              }
            ]
            endPoint Solid {
              translation 0 -5.624828165360588e-23 -0.15000000000000002
              rotation 1 0 0 0
              children [
                DEF foot Shape {
                  appearance VarnishedPine {
                  }
                  geometry Box {
                    size 0.025 0.025 0.1
                  }
                }
              ]
              boundingObject USE foot
              physics Physics {
                centerOfMass [
                  0 0 0
                ]
              }
            }
          }
          DEF femur Shape {
            appearance RustyMetal {
            }
            geometry Box {
              size 0.05 0.05 0.2
            }
          }
        ]
        boundingObject USE femur
        physics Physics {
        }
      }
    }
    DEF FL HingeJoint {
      jointParameters HingeJointParameters {
        anchor -0.25 0.3 0
      }
      device [
        RotationalMotor {
        }
      ]
      endPoint Solid {
        translation -0.25 0.3 -0.1
        rotation 1 0 0 0
        children [
          HingeJoint {
            jointParameters HingeJointParameters {
              anchor 0 0 -0.1
            }
            device [
              RotationalMotor {
              }
            ]
            endPoint Solid {
              translation 0 1.6601845766184287e-19 -0.14999999999999997
              rotation 1 0 0 0
              children [
                DEF foot Shape {
                  appearance VarnishedPine {
                  }
                  geometry Box {
                    size 0.025 0.025 0.1
                  }
                }
              ]
              boundingObject USE foot
              physics Physics {
                centerOfMass [
                  0 0 0
                ]
              }
            }
          }
          DEF femur Shape {
            appearance Pcb {
            }
            geometry Box {
              size 0.05 0.05 0.2
            }
          }
        ]
        name "solid(2)"
        boundingObject USE femur
        physics Physics {
        }
      }
    }
    DEF RR HingeJoint {
      jointParameters HingeJointParameters {
        anchor 0.25 -0.3 0
      }
      device [
        RotationalMotor {
        }
      ]
      endPoint Solid {
        translation 0.25 -0.3 -0.09999999999999995
        rotation 1 0 0 0
        children [
          HingeJoint {
            jointParameters HingeJointParameters {
              anchor 0 0 -0.1
            }
            device [
              RotationalMotor {
              }
            ]
            endPoint Solid {
              translation 0 3.469446951953614e-18 -0.1500000000000002
              rotation 1 0 0 0
              children [
                DEF foot Shape {
                  appearance VarnishedPine {
                  }
                  geometry Box {
                    size 0.025 0.025 0.1
                  }
                }
              ]
              boundingObject USE foot
              physics Physics {
                centerOfMass [
                  0 0 0
                ]
              }
            }
          }
          DEF femur Shape {
            appearance BlanketFabric {
            }
            geometry Box {
              size 0.05 0.05 0.2
            }
          }
        ]
        name "solid(3)"
        boundingObject USE femur
        physics Physics {
        }
      }
    }
    DEF RL HingeJoint {
      jointParameters HingeJointParameters {
        anchor -0.25 -0.3 0
      }
      device [
        RotationalMotor {
        }
      ]
      endPoint Solid {
        translation -0.25 -0.3 -0.1
        rotation 1 0 0 0
        children [
          HingeJoint {
            jointParameters HingeJointParameters {
              anchor 0 0 -0.1
            }
            device [
              RotationalMotor {
              }
            ]
            endPoint Solid {
              translation 0 2.832114216148857e-16 -0.15000000000000008
              rotation 1 0 0 0
              children [
                DEF foot Shape {
                  appearance VarnishedPine {
                  }
                  geometry Box {
                    size 0.025 0.025 0.1
                  }
                }
              ]
              boundingObject USE foot
              physics Physics {
                centerOfMass [
                  0 0 0
                ]
              }
            }
          }
          DEF femur Shape {
            appearance Grass {
            }
            geometry Box {
              size 0.05 0.05 0.2
            }
          }
        ]
        name "solid(4)"
        boundingObject USE femur
        physics Physics {
        }
      }
    }
  ]
  boundingObject USE body
  physics Physics {
  }
}
