#VRML_SIM R2023b utf8

EXTERNPROTO "https://raw.githubusercontent.com/cyberbotics/webots/R2023b/projects/objects/backgrounds/protos/TexturedBackground.proto"
EXTERNPROTO "https://raw.githubusercontent.com/cyberbotics/webots/R2023b/projects/objects/backgrounds/protos/TexturedBackgroundLight.proto"
EXTERNPROTO "https://raw.githubusercontent.com/cyberbotics/webots/R2023b/projects/objects/floors/protos/RectangleArena.proto"
EXTERNPROTO "https://raw.githubusercontent.com/cyberbotics/webots/R2023b/projects/appearances/protos/DamascusSteel.proto"
EXTERNPROTO "https://raw.githubusercontent.com/cyberbotics/webots/R2023b/projects/appearances/protos/VarnishedPine.proto"
EXTERNPROTO "https://raw.githubusercontent.com/cyberbotics/webots/R2023b/projects/appearances/protos/Pcb.proto"
EXTERNPROTO "https://raw.githubusercontent.com/cyberbotics/webots/R2023b/projects/appearances/protos/DryMud.proto"
EXTERNPROTO "https://raw.githubusercontent.com/cyberbotics/webots/R2023b/projects/appearances/protos/BlanketFabric.proto"

WorldInfo {
  CFM 1e-06
  ERP 0.8
}
Viewpoint {
  orientation -0.19610013381075134 0.22200335242073702 0.9551226355988846 1.492724224717996
  position -0.18955133549955472 -2.034494798127468 1.2245971775293591
  follow "alpha_bear:Body"
  followType "Pan and Tilt Shot"
}
TexturedBackground {
}
TexturedBackgroundLight {
}
RectangleArena {
  floorSize 5 5
}
Robot {
  translation 0 0 0.35
  children [
    Gyro {
      name "alpha_gyro"
      boundingObject Box {
        size 0.2 0.4 0.058
      }
      physics Physics {
        mass 0.01
      }
    }
    DEF FR_shoulder HingeJoint {
      jointParameters HingeJointParameters {
        axis 0 1 0
        anchor 0.25 0.3 0
      }
      device [
        PositionSensor {
          name "FR_shoulder_feedback"
        }
        RotationalMotor {
          name "FR_shoulder_servo"
          maxVelocity 50
        }
      ]
      endPoint Solid {
        translation 0.08 0.16 0
        rotation 0 1 0 0
        children [
          HingeJoint {
            jointParameters HingeJointParameters {
              anchor 0.05 0 0
            }
            device [
              PositionSensor {
                name "FR_femur_feedback"
              }
              RotationalMotor {
                name "FR_femur_servo"
                maxVelocity 50
              }
            ]
            endPoint Solid {
              translation 0.05 0 -0.075
              rotation 1 0 0 0
              children [
                HingeJoint {
                  jointParameters HingeJointParameters {
                    anchor 0 0 -0.075
                  }
                  device [
                    PositionSensor {
                      name "FR_tibia_feedback"
                    }
                    RotationalMotor {
                      name "FR_tibia_servo"
                      maxVelocity 50
                    }
                  ]
                  endPoint Solid {
                    translation 0 1.66018e-19 -0.167
                    rotation 1 0 0 0
                    children [
                      Solid {
                        translation 0 0 -0.08
                        children [
                          TouchSensor {
                            children [
                              DEF Foot_ball Shape {
                                appearance BlanketFabric {
                                }
                                geometry Sphere {
                                  radius 0.02
                                }
                              }
                            ]
                            name "FR_touch_sensor"
                            boundingObject USE Foot_ball
                          }
                        ]
                        name "FR_foot_ball"
                        boundingObject DEF Foot_ball Shape {
                          appearance BlanketFabric {
                          }
                          geometry Sphere {
                            radius 0.02
                          }
                        }
                        physics Physics {
                          mass 0.001
                          damping Damping {
                          }
                        }
                      }
                      DEF foot Shape {
                        appearance VarnishedPine {
                        }
                        geometry Box {
                          size 0.025 0.025 0.18369
                        }
                      }
                    ]
                    name "FR_tibia"
                    boundingObject USE foot
                    physics Physics {
                      mass 0.001
                      centerOfMass [
                        0 0 0
                      ]
                    }
                  }
                }
                DEF femur Shape {
                  appearance Pcb {
                  }
                  geometry Box {
                    size 0.03 0.03 0.15
                  }
                }
              ]
              name "FR_femur"
              boundingObject USE femur
              physics Physics {
                mass 0.01
              }
            }
          }
          DEF soulder Shape {
            appearance DryMud {
            }
            geometry Box {
              size 0.05 0.05 0.05
            }
          }
        ]
        name "FR_shoulder"
        boundingObject USE soulder
        physics Physics {
          mass 0.1
        }
      }
    }
    DEF FL_shoulder HingeJoint {
      jointParameters HingeJointParameters {
        axis 0 1 0
        anchor -0.25 0.3 0
      }
      device [
        PositionSensor {
          name "FL_shoulder_feedback"
        }
        RotationalMotor {
          name "FL_shoulder_servo"
          maxVelocity 50
        }
      ]
      endPoint Solid {
        translation -0.08 0.16 0
        rotation 0 1 0 0
        children [
          HingeJoint {
            jointParameters HingeJointParameters {
              anchor -0.05 0 0
            }
            device [
              PositionSensor {
                name "FL_femur_feedback"
              }
              RotationalMotor {
                name "FL_femur_servo"
                maxVelocity 50
              }
            ]
            endPoint Solid {
              translation -0.05 0 -0.075
              rotation 1 0 0 0
              children [
                HingeJoint {
                  jointParameters HingeJointParameters {
                    anchor 0 0 -0.075
                  }
                  device [
                    PositionSensor {
                      name "FL_tibia_feedback"
                    }
                    RotationalMotor {
                      name "FL_tibia_servo"
                      maxVelocity 50
                    }
                  ]
                  endPoint Solid {
                    translation 0 1.66018e-19 -0.167
                    rotation 1 0 0 0
                    children [
                      Solid {
                        translation 0 0 -0.08
                        children [
                          TouchSensor {
                            children [
                              DEF Foot_ball Shape {
                                appearance BlanketFabric {
                                }
                                geometry Sphere {
                                  radius 0.02
                                }
                              }
                            ]
                            name "FL_touch_sensor"
                            boundingObject USE Foot_ball
                          }
                        ]
                        name "FL_foot_ball"
                        boundingObject USE Foot_ball
                        physics Physics {
                          mass 0.001
                          damping Damping {
                          }
                        }
                      }
                      DEF foot Shape {
                        appearance VarnishedPine {
                        }
                        geometry Box {
                          size 0.025 0.025 0.18369
                        }
                      }
                    ]
                    name "FL_tibia"
                    boundingObject USE foot
                    physics Physics {
                      mass 0.001
                      centerOfMass [
                        0 0 0
                      ]
                    }
                  }
                }
                DEF femur Shape {
                  appearance Pcb {
                  }
                  geometry Box {
                    size 0.03 0.03 0.15
                  }
                }
              ]
              name "FL_femur"
              boundingObject USE femur
              physics Physics {
                mass 0.01
              }
            }
          }
          DEF soulder Shape {
            appearance DryMud {
            }
            geometry Box {
              size 0.05 0.05 0.05
            }
          }
        ]
        name "FL_shoulder"
        boundingObject USE soulder
        physics Physics {
          mass 0.1
        }
      }
    }
    DEF RR_shoulder HingeJoint {
      jointParameters HingeJointParameters {
        axis 0 1 0
        anchor 0.25 -0.3 0
      }
      device [
        PositionSensor {
          name "RR_shoulder_feedback"
        }
        RotationalMotor {
          name "RR_shoulder_servo"
          maxVelocity 50
        }
      ]
      endPoint Solid {
        translation 0.08 -0.16 0
        rotation 0 1 0 0
        children [
          HingeJoint {
            jointParameters HingeJointParameters {
              anchor 0.05 0 0
            }
            device [
              PositionSensor {
                name "RR_femur_feedback"
              }
              RotationalMotor {
                name "RR_femur_servo"
                maxVelocity 50
              }
            ]
            endPoint Solid {
              translation 0.05 0 -0.075
              rotation 1 0 0 0
              children [
                HingeJoint {
                  jointParameters HingeJointParameters {
                    anchor 0 0 -0.075
                  }
                  device [
                    PositionSensor {
                      name "RR_tibia_feedback"
                    }
                    RotationalMotor {
                      name "RR_tibia_servo"
                      maxVelocity 50
                    }
                  ]
                  endPoint Solid {
                    translation 0 1.66018e-19 -0.167
                    rotation 1 0 0 0
                    children [
                      Solid {
                        translation 0 0 -0.08
                        children [
                          TouchSensor {
                            children [
                              DEF Foot_ball Shape {
                                appearance BlanketFabric {
                                }
                                geometry Sphere {
                                  radius 0.02
                                }
                              }
                            ]
                            name "RR_touch_sensor"
                            boundingObject USE Foot_ball
                          }
                        ]
                        name "RR_foot_ball"
                        boundingObject USE Foot_ball
                        physics Physics {
                          mass 0.001
                          damping Damping {
                          }
                        }
                      }
                      DEF foot Shape {
                        appearance VarnishedPine {
                        }
                        geometry Box {
                          size 0.025 0.025 0.18369
                        }
                      }
                    ]
                    name "RR_tibia"
                    boundingObject USE foot
                    physics Physics {
                      mass 0.001
                      centerOfMass [
                        0 0 0
                      ]
                    }
                  }
                }
                DEF femur Shape {
                  appearance Pcb {
                  }
                  geometry Box {
                    size 0.03 0.03 0.15
                  }
                }
              ]
              name "RR_femur"
              boundingObject USE femur
              physics Physics {
                mass 0.01
              }
            }
          }
          DEF soulder Shape {
            appearance DryMud {
            }
            geometry Box {
              size 0.05 0.05 0.05
            }
          }
        ]
        name "RR_shoulder"
        boundingObject USE soulder
        physics Physics {
          mass 0.1
        }
      }
    }
    DEF RL_shoulder HingeJoint {
      jointParameters HingeJointParameters {
        axis 0 1 0
        anchor -0.25 -0.3 0
      }
      device [
        PositionSensor {
          name "RL_shoulder_feedback"
        }
        RotationalMotor {
          name "RL_shoulder_servo"
          maxVelocity 50
        }
      ]
      endPoint Solid {
        translation -0.08 -0.16 0
        rotation 0 1 0 0
        children [
          HingeJoint {
            jointParameters HingeJointParameters {
              anchor -0.05 0 0
            }
            device [
              PositionSensor {
                name "RL_femur_feedback"
              }
              RotationalMotor {
                name "RL_femur_servo"
                maxVelocity 50
              }
            ]
            endPoint Solid {
              translation -0.05 0 -0.075
              rotation 1 0 0 0
              children [
                HingeJoint {
                  jointParameters HingeJointParameters {
                    anchor 0 0 -0.075
                  }
                  device [
                    PositionSensor {
                      name "RL_tibia_feedback"
                    }
                    RotationalMotor {
                      name "RL_tibia_servo"
                      maxVelocity 50
                    }
                  ]
                  endPoint Solid {
                    translation 0 1.66018e-19 -0.167
                    rotation 1 0 0 0
                    children [
                      Solid {
                        translation 0 0 -0.08
                        children [
                          TouchSensor {
                            children [
                              DEF Foot_ball Shape {
                                appearance BlanketFabric {
                                }
                                geometry Sphere {
                                  radius 0.02
                                }
                              }
                            ]
                            name "RL_touch_sensor"
                            boundingObject USE Foot_ball
                          }
                        ]
                        name "RL_foot_ball"
                        boundingObject USE Foot_ball
                        physics Physics {
                          mass 0.001
                          damping Damping {
                          }
                        }
                      }
                      DEF foot Shape {
                        appearance VarnishedPine {
                        }
                        geometry Box {
                          size 0.025 0.025 0.18369
                        }
                      }
                    ]
                    name "RL_tibia"
                    boundingObject USE foot
                    physics Physics {
                      mass 0.001
                      centerOfMass [
                        0 0 0
                      ]
                    }
                  }
                }
                DEF femur Shape {
                  appearance Pcb {
                  }
                  geometry Box {
                    size 0.03 0.03 0.15
                  }
                }
              ]
              name "RL_femur"
              boundingObject USE femur
              physics Physics {
                mass 0.01
              }
            }
          }
          DEF soulder Shape {
            appearance DryMud {
            }
            geometry Box {
              size 0.05 0.05 0.05
            }
          }
        ]
        name "RL_shoulder"
        boundingObject USE soulder
        physics Physics {
          mass 0.1
        }
      }
    }
    DEF solid_body Solid {
      children [
        Accelerometer {
          name "alpha_accel"
          boundingObject Box {
            size 0.2 0.4 0.058
          }
          physics Physics {
            mass 0.01
          }
        }
        DEF body Shape {
          appearance DamascusSteel {
          }
          geometry Box {
            size 0.2 0.4 0.0508
          }
        }
      ]
      name "Body"
      boundingObject Box {
        size 0.04 0.05 0.01
      }
      physics Physics {
        damping Damping {
        }
      }
    }
    InertialUnit {
      name "alpha_imu"
      boundingObject USE body
      physics Physics {
        mass 0.01
      }
    }
  ]
  name "alpha_bear"
  boundingObject USE body
  physics Physics {
    mass 1
  }
  controller "<extern>"
}
